2017-06-20 02:16:19,619 (29135/MainThread) mycli.main ERROR - sql: ' show tables from databases;', error: ProgrammingError(1064, "You have an error in your SQL syntax; check the manual that corresponds to your MySQL server version for the right syntax to use near 'databases' at line 1")
2017-06-20 02:16:19,623 (29135/MainThread) mycli.main ERROR - traceback: 'Traceback (most recent call last):\n  File "/usr/lib/python3.6/site-packages/mycli/sqlexecute.py", line 128, in run\n    for result in special.execute(cur, sql):\n  File "/usr/lib/python3.6/site-packages/mycli/packages/special/main.py", line 56, in execute\n    raise CommandNotFound\nmycli.packages.special.main.CommandNotFound\n\nDuring handling of the above exception, another exception occurred:\n\nTraceback (most recent call last):\n  File "/usr/lib/python3.6/site-packages/mycli/main.py", line 522, in one_iteration\n    for title, cur, headers, status in res:\n  File "/usr/lib/python3.6/site-packages/mycli/sqlexecute.py", line 131, in run\n    yield self.execute_normal_sql(sql)\n  File "/usr/lib/python3.6/site-packages/mycli/sqlexecute.py", line 136, in execute_normal_sql\n    num_rows = cur.execute(split_sql)\n  File "/usr/lib/python3.6/site-packages/pymysql/cursors.py", line 166, in execute\n    result = self._query(query)\n  File "/usr/lib/python3.6/site-packages/pymysql/cursors.py", line 322, in _query\n    conn.query(q)\n  File "/usr/lib/python3.6/site-packages/pymysql/connections.py", line 856, in query\n    self._affected_rows = self._read_query_result(unbuffered=unbuffered)\n  File "/usr/lib/python3.6/site-packages/pymysql/connections.py", line 1057, in _read_query_result\n    result.read()\n  File "/usr/lib/python3.6/site-packages/pymysql/connections.py", line 1340, in read\n    first_packet = self.connection._read_packet()\n  File "/usr/lib/python3.6/site-packages/pymysql/connections.py", line 1014, in _read_packet\n    packet.check_error()\n  File "/usr/lib/python3.6/site-packages/pymysql/connections.py", line 393, in check_error\n    err.raise_mysql_exception(self._data)\n  File "/usr/lib/python3.6/site-packages/pymysql/err.py", line 107, in raise_mysql_exception\n    raise errorclass(errno, errval)\npymysql.err.ProgrammingError: (1064, "You have an error in your SQL syntax; check the manual that corresponds to your MySQL server version for the right syntax to use near \'databases\' at line 1")\n'
2017-06-20 02:16:26,970 (29135/MainThread) mycli.main ERROR - sql: 'show tables;', error: InternalError(1046, 'No database selected')
2017-06-20 02:16:26,971 (29135/MainThread) mycli.main ERROR - traceback: 'Traceback (most recent call last):\n  File "/usr/lib/python3.6/site-packages/mycli/sqlexecute.py", line 128, in run\n    for result in special.execute(cur, sql):\n  File "/usr/lib/python3.6/site-packages/mycli/packages/special/main.py", line 56, in execute\n    raise CommandNotFound\nmycli.packages.special.main.CommandNotFound\n\nDuring handling of the above exception, another exception occurred:\n\nTraceback (most recent call last):\n  File "/usr/lib/python3.6/site-packages/mycli/main.py", line 522, in one_iteration\n    for title, cur, headers, status in res:\n  File "/usr/lib/python3.6/site-packages/mycli/sqlexecute.py", line 131, in run\n    yield self.execute_normal_sql(sql)\n  File "/usr/lib/python3.6/site-packages/mycli/sqlexecute.py", line 136, in execute_normal_sql\n    num_rows = cur.execute(split_sql)\n  File "/usr/lib/python3.6/site-packages/pymysql/cursors.py", line 166, in execute\n    result = self._query(query)\n  File "/usr/lib/python3.6/site-packages/pymysql/cursors.py", line 322, in _query\n    conn.query(q)\n  File "/usr/lib/python3.6/site-packages/pymysql/connections.py", line 856, in query\n    self._affected_rows = self._read_query_result(unbuffered=unbuffered)\n  File "/usr/lib/python3.6/site-packages/pymysql/connections.py", line 1057, in _read_query_result\n    result.read()\n  File "/usr/lib/python3.6/site-packages/pymysql/connections.py", line 1340, in read\n    first_packet = self.connection._read_packet()\n  File "/usr/lib/python3.6/site-packages/pymysql/connections.py", line 1014, in _read_packet\n    packet.check_error()\n  File "/usr/lib/python3.6/site-packages/pymysql/connections.py", line 393, in check_error\n    err.raise_mysql_exception(self._data)\n  File "/usr/lib/python3.6/site-packages/pymysql/err.py", line 107, in raise_mysql_exception\n    raise errorclass(errno, errval)\npymysql.err.InternalError: (1046, \'No database selected\')\n'
2017-06-20 02:16:48,993 (29135/MainThread) mycli.main ERROR - sql: '\\!ls', error: ProgrammingError(1064, "You have an error in your SQL syntax; check the manual that corresponds to your MySQL server version for the right syntax to use near '\\!ls' at line 1")
2017-06-20 02:16:48,993 (29135/MainThread) mycli.main ERROR - traceback: 'Traceback (most recent call last):\n  File "/usr/lib/python3.6/site-packages/mycli/sqlexecute.py", line 128, in run\n    for result in special.execute(cur, sql):\n  File "/usr/lib/python3.6/site-packages/mycli/packages/special/main.py", line 56, in execute\n    raise CommandNotFound\nmycli.packages.special.main.CommandNotFound\n\nDuring handling of the above exception, another exception occurred:\n\nTraceback (most recent call last):\n  File "/usr/lib/python3.6/site-packages/mycli/main.py", line 522, in one_iteration\n    for title, cur, headers, status in res:\n  File "/usr/lib/python3.6/site-packages/mycli/sqlexecute.py", line 131, in run\n    yield self.execute_normal_sql(sql)\n  File "/usr/lib/python3.6/site-packages/mycli/sqlexecute.py", line 136, in execute_normal_sql\n    num_rows = cur.execute(split_sql)\n  File "/usr/lib/python3.6/site-packages/pymysql/cursors.py", line 166, in execute\n    result = self._query(query)\n  File "/usr/lib/python3.6/site-packages/pymysql/cursors.py", line 322, in _query\n    conn.query(q)\n  File "/usr/lib/python3.6/site-packages/pymysql/connections.py", line 856, in query\n    self._affected_rows = self._read_query_result(unbuffered=unbuffered)\n  File "/usr/lib/python3.6/site-packages/pymysql/connections.py", line 1057, in _read_query_result\n    result.read()\n  File "/usr/lib/python3.6/site-packages/pymysql/connections.py", line 1340, in read\n    first_packet = self.connection._read_packet()\n  File "/usr/lib/python3.6/site-packages/pymysql/connections.py", line 1014, in _read_packet\n    packet.check_error()\n  File "/usr/lib/python3.6/site-packages/pymysql/connections.py", line 393, in check_error\n    err.raise_mysql_exception(self._data)\n  File "/usr/lib/python3.6/site-packages/pymysql/err.py", line 107, in raise_mysql_exception\n    raise errorclass(errno, errval)\npymysql.err.ProgrammingError: (1064, "You have an error in your SQL syntax; check the manual that corresponds to your MySQL server version for the right syntax to use near \'\\\\!ls\' at line 1")\n'
2017-06-20 02:16:53,274 (29135/MainThread) mycli.main ERROR - sql: '\\! ls', error: ProgrammingError(1064, "You have an error in your SQL syntax; check the manual that corresponds to your MySQL server version for the right syntax to use near '\\! ls' at line 1")
2017-06-20 02:16:53,275 (29135/MainThread) mycli.main ERROR - traceback: 'Traceback (most recent call last):\n  File "/usr/lib/python3.6/site-packages/mycli/sqlexecute.py", line 128, in run\n    for result in special.execute(cur, sql):\n  File "/usr/lib/python3.6/site-packages/mycli/packages/special/main.py", line 56, in execute\n    raise CommandNotFound\nmycli.packages.special.main.CommandNotFound\n\nDuring handling of the above exception, another exception occurred:\n\nTraceback (most recent call last):\n  File "/usr/lib/python3.6/site-packages/mycli/main.py", line 522, in one_iteration\n    for title, cur, headers, status in res:\n  File "/usr/lib/python3.6/site-packages/mycli/sqlexecute.py", line 131, in run\n    yield self.execute_normal_sql(sql)\n  File "/usr/lib/python3.6/site-packages/mycli/sqlexecute.py", line 136, in execute_normal_sql\n    num_rows = cur.execute(split_sql)\n  File "/usr/lib/python3.6/site-packages/pymysql/cursors.py", line 166, in execute\n    result = self._query(query)\n  File "/usr/lib/python3.6/site-packages/pymysql/cursors.py", line 322, in _query\n    conn.query(q)\n  File "/usr/lib/python3.6/site-packages/pymysql/connections.py", line 856, in query\n    self._affected_rows = self._read_query_result(unbuffered=unbuffered)\n  File "/usr/lib/python3.6/site-packages/pymysql/connections.py", line 1057, in _read_query_result\n    result.read()\n  File "/usr/lib/python3.6/site-packages/pymysql/connections.py", line 1340, in read\n    first_packet = self.connection._read_packet()\n  File "/usr/lib/python3.6/site-packages/pymysql/connections.py", line 1014, in _read_packet\n    packet.check_error()\n  File "/usr/lib/python3.6/site-packages/pymysql/connections.py", line 393, in check_error\n    err.raise_mysql_exception(self._data)\n  File "/usr/lib/python3.6/site-packages/pymysql/err.py", line 107, in raise_mysql_exception\n    raise errorclass(errno, errval)\npymysql.err.ProgrammingError: (1064, "You have an error in your SQL syntax; check the manual that corresponds to your MySQL server version for the right syntax to use near \'\\\\! ls\' at line 1")\n'
2017-06-20 02:17:12,017 (29135/MainThread) mycli.main ERROR - sql: '\\g', error: ProgrammingError(1064, "You have an error in your SQL syntax; check the manual that corresponds to your MySQL server version for the right syntax to use near '\\g' at line 1")
2017-06-20 02:17:12,018 (29135/MainThread) mycli.main ERROR - traceback: 'Traceback (most recent call last):\n  File "/usr/lib/python3.6/site-packages/mycli/sqlexecute.py", line 128, in run\n    for result in special.execute(cur, sql):\n  File "/usr/lib/python3.6/site-packages/mycli/packages/special/main.py", line 56, in execute\n    raise CommandNotFound\nmycli.packages.special.main.CommandNotFound\n\nDuring handling of the above exception, another exception occurred:\n\nTraceback (most recent call last):\n  File "/usr/lib/python3.6/site-packages/mycli/main.py", line 522, in one_iteration\n    for title, cur, headers, status in res:\n  File "/usr/lib/python3.6/site-packages/mycli/sqlexecute.py", line 131, in run\n    yield self.execute_normal_sql(sql)\n  File "/usr/lib/python3.6/site-packages/mycli/sqlexecute.py", line 136, in execute_normal_sql\n    num_rows = cur.execute(split_sql)\n  File "/usr/lib/python3.6/site-packages/pymysql/cursors.py", line 166, in execute\n    result = self._query(query)\n  File "/usr/lib/python3.6/site-packages/pymysql/cursors.py", line 322, in _query\n    conn.query(q)\n  File "/usr/lib/python3.6/site-packages/pymysql/connections.py", line 856, in query\n    self._affected_rows = self._read_query_result(unbuffered=unbuffered)\n  File "/usr/lib/python3.6/site-packages/pymysql/connections.py", line 1057, in _read_query_result\n    result.read()\n  File "/usr/lib/python3.6/site-packages/pymysql/connections.py", line 1340, in read\n    first_packet = self.connection._read_packet()\n  File "/usr/lib/python3.6/site-packages/pymysql/connections.py", line 1014, in _read_packet\n    packet.check_error()\n  File "/usr/lib/python3.6/site-packages/pymysql/connections.py", line 393, in check_error\n    err.raise_mysql_exception(self._data)\n  File "/usr/lib/python3.6/site-packages/pymysql/err.py", line 107, in raise_mysql_exception\n    raise errorclass(errno, errval)\npymysql.err.ProgrammingError: (1064, "You have an error in your SQL syntax; check the manual that corresponds to your MySQL server version for the right syntax to use near \'\\\\g\' at line 1")\n'
